<?xml version="1.0"?>
<robot xmlns:xacro="http://ros.org/wiki/xacro">

<xacro:macro name="joint_revolute" params="prefix parent xyz rpy lower upper axis">
	<joint name="${prefix}_joint" type="revolute">
		<origin xyz="${xyz}" rpy="${rpy}"/>
		<parent link="${parent}"/>
      		<child link="${prefix}_link"/>
     		<limit lower="${lower}" upper="${upper}" effort="100" velocity="100"/>   
		<axis xyz="${axis}"/> 
    	</joint>

	<link name="${prefix}_link"/>

</xacro:macro>

<xacro:macro name="joint_revolute_tube" params="prefix parent xyz rpy lower upper axis length" >
	<joint name="${prefix}_joint" type="revolute">
		<origin xyz="${xyz}" rpy="${rpy}"/>
		<parent link="${parent}"/>
      		<child link="${prefix}_link"/>
     		<limit lower="${lower}" upper="${upper}" effort="100" velocity="100"/>   
		<axis xyz="${axis}"/> 
    	</joint>

	<link name="${prefix}_link"/>

</xacro:macro>


<xacro:macro name="joint_fixed" params="prefix parent xyz rpy" >
	<joint name="${prefix}_joint" type="fixed">
		<origin xyz="${xyz}" rpy="${rpy}"/>
		<parent link="${parent}"/>
      		<child link="${prefix}_link"/> 
    	</joint>

	<link name="${prefix}_link"/>

</xacro:macro>

</robot>
